Workbook

Sheet MANZ. A
B3: SERVIU REGION DE LA ARAUCANIA | C3: CUADRO RESUMEN DE CONTROL RECEPCIONADO
A6: OBRA | B6: CAMPOS DEL SUR II | C6: FECHA | G6: 12.02.2025 | J6: R3 | N6: R18 | R6: R28 | V6: R38 | Z6: R55 | AD6: R74 | AH6: R98 | AL6: R112
A7: COMUNA | B7: RENAICO | J7: R7 | N7: R19 | R7: R29 | V7: R39 | Z7: R58 | AD7: R81 | AH7: R99 | AL7: R113
A8: CONTRATISTA | B8: CONSTRUCTORA CIMOL S.P.A | J8: R9 | N8: R20 | R8: R30 | V8: R41 | Z8: R60 | AD8: R83 | AH8: R100 | AL8: R114
A9: RESIDENTE DE OBRA | B9: EDGAR MORALES ALARCON | J9: R10 | N9: R21 | R9: R31 | V9: R42 | Z9: R61 | AD9: R84 | AH9: R101 | AL9: R116
A10: AUTOCONTROL | B10: IGNACIO MEDINA MEDINA | J10: R11 | N10: R22 | R10: R32 | V10: R44 | Z10: R63 | AD10: R85 | AH10: R104 | AL10: R117
A11: AUTOCONTROL | B11: MICHEL BERGER HUICHANAO | J11: R12 | N11: R23 | R11: R33 | V11: R45 | Z11: R64 | AD11: R86 | AH11: R105
A12: E.P. | B12: PLAN SOCIAL | C12: VERSION | G12: 1.0 | J12: R13 | N12: R24 | R12: R34 | V12: R46 | Z12: R65 | AD12: R87 | AH12: R106
A13: S.A.T. | B13: OBED CEA LONCONADO | J13: R14 | N13: R25 | R13: R35 | V13: R47 | Z13: R67 | AD13: R88 | AH13: R107
A14: F.T.O. | J14: R15 | N14: R26 | R14: R36 | V14: R51 | Z14: R68 | AD14: R90 | AH14: R109
A15: CODIGO | B15: 182948 | J15: R16 | N15: R27 | R15: R37 | V15: R52 | Z15: R69 | AD15: R95 | AH15: R110
A17: ITEM | B17: DESIGNACIÓN | C17: UBICACIÓN
C18: VIVIENDA LOTE Nº | AD18: MANZANA : | AJ18: A
C19: 1 | E19: 2 | G19: T. REV | H19: TOTAL
A20: B | B20: OBRA GRUESA | C20: AT | D20: RV | E20: AT | F20: RV
A21: B.1 | B21: FUNDACIONES
A22: B.1.1 | B22: Replanteo, trazado y niveles | C22: R37 | E22: R37
A23: B.1.2 | B23: Excavación | C23: R37 | E23: R37
A24: B.1.3 | B24: Emplantillado (G5) | C24: R37 | E24: R37
A25: B.1.4 | B25: Hormigón cimientos (G10) | C25: R37 | E25: R37
A26: B.1.5 | B26: Hormigón sobrecimientos (G17) | C26: R37 | E26: R37
A27: B.1.6 | B27: Enfierradura | C27: R37 | E27: R37
A28: B.1.7 | B28: Moldajes | C28: R37 | E28: R37
A29: B.2 | B29: RADIER
A30: B.2.1 | B30: Base (Cama de ripio) e=0,08 mts
A31: B.2.2 | B31: Hormigón (G15)
A32: B.3 | B32: MUROS 1 piso
A33: B.3.3.1 | B33: Entramado Estructural
A34: B.4 | B34: ESTRUCTURA HORIZONTAL (ENTREPISO)
A35: B.4.4.1 | B35: Madera
A36: B.4.4.2 | B36: Terciado estructural (15mm)
A37: B.5 | B37: MUROS 2 piso
A38: B.5.3.1 | B38: Entramado Estructural (2do P)
A39: B.6 | B39: CUBIERTA
A40: B.6.1.1 | B40: Madera
... A166: D.EX.4 | B166: Timbre de luz
B180: ADMINISTRADOR DE OBRA | F180: AUTOCONTROL | W180: F.T.O | AI180: S.A.T.
B181: EDGAR MORALES ALARCON | F181: IGNACIO MEDINA MEDINA | AN181: OBED CEA LONCONADO

Sheet MANZ. B
B1: SERVIU REGION DE LA ARAUCANIA | C1: CUADRO RESUMEN DE CONTROL RECEPCIONADO
A4: OBRA | B4: CAMPOS DEL SUR II | C4: FECHA | E4: 46037 | G4: R20 | H4: 45933
A5: COMUNA | B5: RENAICO | G5: R23 | H5: 45954
A6: CONTRATISTA | B6: CONSTRUCTORA CIMOL S.P.A | G6: R24 | H6: 45960
A7: RESIDENTE DE OBRA | B7: EDGAR MORALES ALARCON | G7: R25 | H7: 45968
A8: AUTOCONTROL | B8: IGNACIO MEDINA MEDINA | G8: R26 | H8: 45975
A9: AUTOCONTROL | B9: MICHEL BERGER HUICHANAO | G9: R27 | H9: 45982
A10: E.P. | B10: PLAN SOCIAL | C10: VERSION | E10: 1.0 | G10: R36 | H10: 46045
A11: S.A.T. | B11: OBED CEA LONCONADO
A12: F.T.O. | B12: MAURICIO DIAZ BARRA
A13: CODIGO | B13: 182948
A15: ITEM | B15: DESIGNACIÓN | C15: UBICACIÓN
C16: VIVIENDA LOTE Nº | K16: MANZANA : | Q16: B
C17: 1 | E17: 2 | G17: 3 | I17: 4 | K17: 5 | M17: 6 | O17: 7 | Q17: T. REV | R17: TOTAL
A18: B | B18: OBRA GRUESA | C18: AT | D18: RV | E18: AT | F18: RV | G18: AT | H18: RV | I18: AT | J18: RV | K18: AT | L18: RV | M18: AT | N18: RV | O18: AT | P18: RV
A19: B.1 | B19: FUNDACIONES
A20: B.1.1 | B20: Replanteo, trazado y niveles | C20: R36 | G20: R20 | I20: R20 | K20: R20 | M20: R20 | Q20: =COUNTIF(C20:P20,">=R") -> 5 | R20: =Q20 -> 5
A21: B.1.2 | B21: Excavación | C21: R36 | G21: R26 | I21: R26 | K21: R26 | M21: R20 | Q21: =COUNTIF(C21:P21,">=R") -> 5 | R21: =Q21 -> 5
A22: B.1.3 | B22: Emplantillado (G5) | C22: R36 | G22: R26 | I22: R26 | K22: R26 | M22: R26 | Q22: =COUNTIF(C22:P22,">=R") -> 5 | R22: =Q22 -> 5
A23: B.1.4 | B23: Hormigón cimientos (G10) | C23: R36 | G23: R26 | I23: R26 | K23: R26 | M23: R26 | Q23: =COUNTIF(C23:P23,">=R") -> 5 | R23: =Q23 -> 5
A24: B.1.5 | B24: Hormigón sobrecimientos (G17) | C24: R36 | G24: R26 | I24: R26 | K24: R25 | M24: R25 | Q24: =COUNTIF(C24:P24,">=R") -> 5 | R24: =Q24 -> 5
A25: B.1.6 | B25: Enfierradura | C25: R36 | G25: R26 | I25: R26 | K25: R25 | M25: R25 | Q25: =COUNTIF(C25:P25,">=R") -> 5 | R25: =Q25 -> 5
A26: B.1.7 | B26: Moldajes | C26: R36 | G26: R26 | I26: R26 | K26: R25 | M26: R25 | Q26: =COUNTIF(C26:P26,">=R") -> 5 | R26: =Q26 -> 5
A27: B.2 | B27: RADIER
A28: B.2.1 | B28: Base (Cama de ripio) e=0,08 mts | C28: R36 | G28: R26 | I28: R26 | K28: R25 | M28: R25 | Q28: =COUNTIF(C28:P28,">=R") -> 5 | R28: =Q28 -> 5
A29: B.2.2 | B29: Hormigón (G15) | C29: R36 | G29: R26 | I29: R26 | K29: R25 | M29: R25 | Q29: =COUNTIF(C29:P29,">=R") -> 5 | R29: =Q29 -> 5
A30: B.3 | B30: MUROS 1 piso
A31: B.3.3.1 | B31: Entramado Estructural | Q31: =COUNTIF(C22:P22,">=R") -> 5 | R31: =Q22 -> 5
A32: B.4 | B32: ESTRUCTURA HORIZONTAL (ENTREPISO)
A33: B.4.4.1 | B33: Madera | Q33: =COUNTIF(C25:P25,">=R") -> 5 | R33: =Q25 -> 5
A34: B.4.4.2 | B34: Terciado estructural (15mm)
A35: B.5 | B35: MUROS 2 piso
A36: B.5.3.1 | B36: Entramado Estructural (2do P) | Q36: =COUNTIF(C29:P29,">=R") -> 5 | R36: =Q29 -> 5
A37: B.6 | B37: CUBIERTA
A38: B.6.1.1 | B38: Madera | Q38: =COUNTIF(C38:P38,">=R") -> 0 | R38: =Q38 -> 0
A39: B.6.2.1 | B39: Acero galvanizado (0.35mm) | Q39: =COUNTIF(C39:P39,">=R") -> 0 | R39: =Q39 -> 0
A40: B.6.3 | B40: Hojalatería | Q40: =COUNTIF(C40:P40,">=R") -> 0 | R40: =Q40 -> 0
A41: B.6.3.1 | B41: Canales | Q41: =COUNTIF(C41:P41,">=R") -> 0 | R41: =Q41 -> 0
A42: B.6.3.2 | B42: Bajadas y Hojalaterias | Q42: =COUNTIF(C42:P42,">=R") -> 0 | R42: =Q42 -> 0
A43: B.6.EX.1 | B43: Caballete | Q43: =COUNTIF(C43:P43,">=R") -> 0 | R43: =Q43 -> 0
...

Sheet MANZ.C
B1: SERVIU REGION DE LA ARAUCANIA | C1: CUADRO RESUMEN DE CONTROL RECEPCIONADO
A4: OBRA | B4: CAMPOS DEL SUR II | C4: FECHA | G4: 46037 | J4: R3 | K4: 45807 | N4: R12 | O4: 45870 | R4: R23 | S4: 45954 | V4: R32 | W4: 46015
A5: COMUNA | B5: RENAICO | J5: R4 | K5: 45814 | N5: R13 | O5: 45883 | R5: R24 | S5: 45960 | V5: R33 | W5: 46022
A6: CONTRATISTA | B6: CONSTRUCTORA CIMOL S.P.A | J6: R5 | K6: 45821 | N6: R14 | O6: 45891 | R6: R25 | S6: 45968 | V6: R34 | W6: 46031
A7: RESIDENTE DE OBRA | B7: EDGAR MORALES ALARCON | J7: R6 | K7: 45827 | N7: R16 | O7: 45905 | R7: R26 | S7: 45975 | V7: R35 | W7: 46038
A8: AUTOCONTROL | B8: MICHEL BERGER HUICHANAO | J8: R7 | K8: 45835 | N8: R17 | O8: 45912 | R8: R27 | S8: 45982 | V8: R36 | W8: 46045
A9: E.P. | B9: PLAN SOCIAL | C9: VERSION | G9: 1.0 | J9: R8 | K9: 45842 | N9: R18 | O9: 45916 | R9: R28 | S9: 45989 | V9: R37 | W9: 46052
A10: S.A.T. | B10: OBED CEA LONCONADO | J10: R9 | K10: 45849 | N10: R20 | O10: 45933 | R10: R29 | S10: 45996
A11: F.T.O. | B11: MAURICIO DIAZ BARRA | J11: R10 | K11: 45855 | N11: R21 | O11: 45940 | R11: R30 | S11: 46003
A12: CODIGO | B12: 182948 | J12: R11 | K12: 45863 | N12: R22 | O12: 45947 | R12: R31 | S12: 46010
A14: ITEM | B14: DESIGNACIÓN | C14: UBICACIÓN
C15: VIVIENDA LOTE Nº | AD15: MANZANA : | AJ15: C
C16: 1 | E16: 2 | G16: 3 | I16: 4 | K16: 5 | M16: 6 | O16: 7 | Q16: 8 | S16: 9 | U16: 10 | W16: 11 | Y16: 12 | AA16: 13 | AC16: 14 | AE16: 15 | AG16: 16 | AI16: 17 | AK16: T. REV | AL16: TOTAL
A17: B | B17: OBRA GRUESA | C17: AT | D17: RV | E17: AT | F17: RV | G17: AT | H17: RV | I17: AT | J17: RV | K17: AT | L17: RV | M17: AT | N17: RV | O17: AT | P17: RV | Q17: AT | R17: RV | S17: AT | T17: RV | U17: AT | V17: RV | W17: AT | X17: RV | Y17: AT | Z17: RV | AA17: AT | AB17: RV | AC17: AT | AD17: RV | AE17: AT | AF17: RV | AG17: AT | AH17: RV | AI17: AT | AJ17: RV
A18: B.1 | B18: FUNDACIONES
A19: B.1.1 | B19: Replanteo, trazado y niveles | C19: R3 | E19: R3 | G19: R3 | I19: R4 | K19: R4 | M19: R4 | O19: R4 | Q19: R7 | S19: R7 | U19: R7 | W19: R7 | Y19: R7 | AA19: R7 | AC19: R7 | AE19: R7 | AG19: R7 | AI19: R7 | AK19: =COUNTIF(C19:AJ19,">=R") -> 17 | AL19: =AK19 -> 17
A20: B.1.2 | B20: Excavación | C20: R3 | E20: R3 | G20: R3 | I20: R4 | K20: R4 | M20: R4 | O20: R4 | Q20: R7 | S20: R8 | U20: R26 | W20: R8 | Y20: R8 | AA20: R8 | AC20: R8 | AE20: R8 | AG20: R8 | AI20: R9 | AK20: =COUNTIF(C20:AJ20,">=R") -> 17 | AL20: =AK20 -> 17
A21: B.1.3 | B21: Emplantillado (G5) | C21: R3 | E21: R3 | G21: R3 | I21: R5 | K21: R5 | M21: R5 | O21: R5 | Q21: R7 | S21: R8 | U21: R9 | W21: R9 | Y21: R8 | AA21: R8 | AC21: R8 | AE21: R8 | AG21: R8 | AI21: R9 | AK21: =COUNTIF(C21:AJ21,">=R") -> 17 | AL21: =AK21 -> 17
A22: B.1.4 | B22: Hormigón cimientos (G10) | C22: R3 | E22: R3 | G22: R3 | I22: R5 | K22: R5 | M22: R5 | O22: R5 | Q22: R7 | S22: R8 | U22: R9 | W22: R9 | Y22: R8 | AA22: R8 | AC22: R8 | AE22: R8 | AG22: R8 | AI22: R9 | AK22: =COUNTIF(C22:AJ22,">=R") -> 17 | AL22: =AK22 -> 17
A23: B.1.5 | B23: Hormigón sobrecimientos (G17) | C23: R4 | E23: R4 | G23: R4 | I23: R5 | K23: R5 | M23: R5 | O23: R5 | Q23: R9 | S23: R9 | U23: R9 | W23: R9 | Y23: R10 | AA23: R10 | AC23: R10 | AE23: R10 | AG23: R10 | AI23: R10 | AK23: =COUNTIF(C23:AJ23,">=R") -> 17 | AL23: =AK23 -> 17
A24: B.1.6 | B24: Enfierradura | C24: R4 | E24: R4 | G24: R4 | I24: R5 | K24: R5 | M24: R5 | O24: R5 | Q24: R9 | S24: R9 | U24: R9 | W24: R9 | Y24: R10 | AA24: R10 | AC24: R10 | AE24: R10 | AG24: R10 | AI24: R10 | AK24: =COUNTIF(C24:AJ24,">=R") -> 17 | AL24: =AK24 -> 17
A25: B.1.7 | B25: Moldajes | C25: R4 | E25: R4 | G25: R4 | I25: R5 | K25: R5 | M25: R5 | O25: R5 | Q25: R9 | S25: R9 | U25: R9 | W25: R9 | Y25: R10 | AA25: R10 | AC25: R10 | AE25: R10 | AG25: R10 | AI25: R10 | AK25: =COUNTIF(C25:AJ25,">=R") -> 17 | AL25: =AK25 -> 17
A26: B.2 | B26: RADIER
A27: B.2.1 | B27: Base (Cama de ripio) e=0,08 mts | C27: R4 | E27: R4 | G27: R4 | I27: R5 | K27: R5 | M27: R5 | O27: R5 | Q27: R9 | S27: R9 | U27: R9 | W27: R9 | Y27: R10 | AA27: R10 | AC27: R10 | AE27: R10 | AG27: R10 | AI27: R10 | AK27: =COUNTIF(C27:AJ27,">=R") -> 17 | AL27: =AK27 -> 17
A28: B.2.2 | B28: Hormigón (G15) | C28: R4 | E28: R4 | G28: R4 | I28: R5 | K28: R5 | M28: R5 | O28: R5 | Q28: R9 | S28: R9 | U28: R9 | W28: R9 | Y28: R10 | AA28: R10 | AC28: R10 | AE28: R10 | AG28: R10 | AI28: R10 | AK28: =COUNTIF(C28:AJ28,">=R") -> 17 | AL28: =AK28 -> 17
A29: B.3 | B29: MUROS 1 piso
A30: B.3.3.1 | B30: Entramado Estructural | C30: R6 | E30: R6 | G30: R6 | I30: R6 | K30: R9 | M30: R9 | O30: R9 | Q30: R12 | S30: R12 | U30: R12 | W30: R12 | Y30: R15 | AA30: R15 | AC30: R15 | AE30: R15 | AG30: R15 | AI30: R15 | AK30: =COUNTIF(C30:AJ30,">=R") -> 17 | AL30: =AK30 -> 17
A31: B.4 | B31: ESTRUCTURA HORIZONTAL (ENTREPISO)
A32: B.4.4.1 | B32: Madera | C32: R7 | E32: R7 | G32: R7 | I32: R7 | K32: R9 | M32: R9 | O32: R9 | Q32: R12 | S32: R12 | U32: R12 | W32: R12 | Y32: R17 | AA32: R17 | AC32: R17 | AE32: R17 | AG32: R17 | AI32: R17 | AK32: =COUNTIF(C32:AJ32,">=R") -> 17 | AL32: =AK32 -> 17
A33: B.4.4.2 | B33: Terciado estructural (15mm) | C33: R7 | E33: R7 | G33: R7 | I33: R7 | K33: R9 | M33: R9 | O33: R9 | Q33: R12 | S33: R12 | U33: R12 | W33: R12 | Y33: R17 | AA33: R17 | AC33: R17 | AE33: R17 | AG33: R17 | AI33: R17 | AK33: =COUNTIF(C33:AJ33,">=R") -> 17 | AL33: =AK33 -> 17
A34: B.5 | B34: MUROS 2 piso
A35: B.5.3.1 | B35: Entramado Estructural (2do P) | C35: R7 | E35: R7 | G35: R7 | I35: R7 | K35: R9 | M35: R9 | O35: R9 | Q35: R12 | S35: R12 | U35: R12 | W35: R12 | Y35: R15 | AA35: R15 | AC35: R15 | AE35: R15 | AG35: R15 | AI35: R15 | AK35: =COUNTIF(C35:AJ35,">=R") -> 17 | AL35: =AK35 -> 17
A36: B.6 | B36: CUBIERTA
A37: B.6.1.1 | B37: Madera | C37: R9 | E37: R9 | G37: R9 | I37: R9 | K37: R9 | M37: R11 | O37: R11 | Q37: R12 | S37: R12 | U37: R12 | W37: R12 | Y37: R15 | AA37: R15 | AC37: R15 | AE37: R15 | AG37: R15 | AI37: R15 | AK37: =COUNTIF(C37:AJ37,">=R") -> 17 | AL37: =AK37 -> 17
A38: B.6.2.1 | B38: Acero galvanizado (0.35mm) | C38: R9 | E38: R9 | G38: R10 | I38: R10 | K38: R10 | M38: R10 | O38: R10 | Q38: R15 | S38: R15 | U38: R15 | W38: R16 | Y38: R16 | AA38: R16 | AC38: R16 | AE38: R16 | AG38: R16 | AI38: R16 | AK38: =COUNTIF(C38:AJ38,">=R") -> 17 | AL38: =AK38 -> 17
A39: B.6.3 | B39: Hojalatería
A40: B.6.3.1 | B40: Canales | C40: R36 | E40: R36 | G40: R36 | I40: R36 | K40: R36 | M40: R36 | O40: R36 | Q40: R36 | S40: R36 | U40: R36 | W40: R36 | Y40: R36 | AA40: R36 | AC40: R36 | AE40: R36 | AG40: R36 | AI40: R36 | AK40: =COUNTIF(C40:AJ40,">=R") -> 17 | AL40: =AK40 -> 17
A41: B.6.3.2 | B41: Bajadas y Hojalaterias
A42: B.6.EX.1 | B42: Caballete | C42: R10 | E42: R10 | G42: R10 | I42: R10 | K42: R10 | M42: R10 | O42: R10 | Q42: R18 | S42: R18 | U42: R18 | W42: R18 | Y42: R18 | AA42: R18 | AC42: R18 | AE42: R18 | AG42: R18 | AI42: R18 | AK42: =COUNTIF(C42:AJ42,">=R") -> 17 | AL42: =AK42 -> 17
A43: B.6.EX.2 | B43: Esquineros | C43: R15 | E43: R15 | G43: R15 | I43: R15 | K43: R15 | M43: R15 | O43: R15 | Q43: R18 | S43: R18 | U43: R18 | W43: R18 | Y43: R18 | AA43: R18 | AC43: R18 | AE43: R18 | AG43: R18 | AI43: R20 | AK43: =COUNTIF(C43:AJ43,">=R") -> 17 | AL43: =AK43 -> 17
...

Sheet MANZ.D
B1: SERVIU REGION DE LA ARAUCANIA | C1: CUADRO RESUMEN DE CONTROL RECEPCIONADO
A4: OBRA | B4: CAMPOS DEL SUR II | C4: FECHA | G4: 46037 | J4: R10 | K4: 45855 | N4: R21 | O4: 45940 | R4: R31 | S4: 46010
A5: COMUNA | B5: RENAICO | J5: R11 | K5: 45863 | N5: R23 | O5: 45954 | R5: R32 | S5: 46015
A6: CONTRATISTA | B6: CONSTRUCTORA CIMOL S.P.A | J6: R12 | K6: 45870 | N6: R24 | O6: 45960 | R6: R33 | S6: 46022
A7: RESIDENTE DE OBRA | B7: EDGAR MORALES ALARCON | J7: R13 | K7: 45883 | N7: R25 | O7: 45968 | R7: R34 | S7: 46031
A8: AUTOCONTROL | B8: MICHEL BERGER HUICHANAO | J8: R14 | K8: 45891 | N8: R26 | O8: 45975 | R8: R35 | S8: 46038
A9: E.P. | B9: PLAN SOCIAL | C9: VERSION | G9: 1.0 | J9: R15 | K9: 45898 | N9: R27 | O9: 45982 | R9: R36 | S9: 46045
A10: S.A.T. | B10: OBED CEA LONCONADO | J10: R17 | K10: 45912 | N10: R28 | O10: 45989 | R10: R37 | S10: 46052
A11: F.T.O. | B11: MAURICIO DIAZ BARRA | J11: R19 | K11: 45926 | N11: R29 | O11: 45996
A12: CODIGO | B12: 182948 | J12: R20 | K12: 45933 | N12: R30 | O12: 46003
A14: ITEM | B14: DESIGNACIÓN | C14: UBICACIÓN
C15: VIVIENDA LOTE Nº | S15: MANZANA : | Y15: D
C16: 1 | E16: 2 | G16: 3 | I16: 4 | K16: 5 | M16: 6 | O16: 7 | Q16: 8 | S16: 9 | U16: 10 | W16: 11 | Y16: T. REV | Z16: TOTAL
A17: B | B17: OBRA GRUESA | C17: AT | D17: RV | E17: AT | F17: RV | G17: AT | H17: RV | I17: AT | J17: RV | K17: AT | L17: RV | M17: AT | N17: RV | O17: AT | P17: RV | Q17: AT | R17: RV | S17: AT | T17: RV | U17: AT | V17: RV | W17: AT | X17: RV
A18: B.1 | B18: FUNDACIONES
A19: B.1.1 | B19: Replanteo, trazado y niveles | C19: R10 | E19: R10 | G19: R10 | I19: R10 | K19: R10 | M19: R10 | O19: R10 | Q19: R10 | S19: R12 | U19: R12 | W19: R12 | Y19: =COUNTIF(C19:X19,">=R") -> 11 | Z19: =Y19 -> 11
A20: B.1.2 | B20: Excavación | C20: R10 | E20: R10 | G20: R10 | I20: R10 | K20: R11 | M20: R11 | O20: R11 | Q20: R11 | S20: R12 | U20: R12 | W20: R13 | Y20: =COUNTIF(C20:X20,">=R") -> 11 | Z20: =Y20 -> 11
A21: B.1.3 | B21: Emplantillado (G5) | C21: R11 | E21: R11 | G21: R11 | I21: R11 | K21: R12 | M21: R12 | O21: R12 | Q21: R12 | S21: R14 | U21: R14 | W21: R14 | Y21: =COUNTIF(C21:X21,">=R") -> 11 | Z21: =Y21 -> 11
A22: B.1.4 | B22: Hormigón cimientos (G10) | C22: R11 | E22: R11 | G22: R11 | I22: R11 | K22: R12 | M22: R12 | O22: R12 | Q22: R12 | S22: R14 | U22: R14 | W22: R14 | Y22: =COUNTIF(C22:X22,">=R") -> 11 | Z22: =Y22 -> 11
A23: B.1.5 | B23: Hormigón sobrecimientos (G17) | C23: R13 | E23: R13 | G23: R13 | I23: R13 | K23: R15 | M23: R14 | O23: R14 | Q23: R14 | S23: R14 | U23: R14 | W23: R15 | Y23: =COUNTIF(C23:X23,">=R") -> 11 | Z23: =Y23 -> 11
A24: B.1.6 | B24: Enfierradura | C24: R13 | E24: R13 | G24: R13 | I24: R13 | K24: R15 | M24: R14 | O24: R14 | Q24: R14 | S24: R14 | U24: R14 | W24: R15 | Y24: =COUNTIF(C24:X24,">=R") -> 11 | Z24: =Y24 -> 11
A25: B.1.7 | B25: Moldajes | C25: R13 | E25: R13 | G25: R13 | I25: R13 | K25: R15 | M25: R14 | O25: R14 | Q25: R14 | S25: R14 | U25: R14 | W25: R15 | Y25: =COUNTIF(C25:X25,">=R") -> 11 | Z25: =Y25 -> 11
A26: B.2 | B26: RADIER
A27: B.2.1 | B27: Base (Cama de ripio) e=0,08 mts | C27: R13 | E27: R13 | G27: R13 | I27: R13 | K27: R15 | M27: R14 | O27: R14 | Q27: R14 | S27: R14 | U27: R14 | W27: R15 | Y27: =COUNTIF(C27:X27,">=R") -> 11 | Z27: =Y27 -> 11
A28: B.2.2 | B28: Hormigón (G15) | C28: R13 | E28: R13 | G28: R13 | I28: R13 | K28: R15 | M28: R14 | O28: R14 | Q28: R14 | S28: R14 | U28: R14 | W28: R15 | Y28: =COUNTIF(C28:X28,">=R") -> 11 | Z28: =Y28 -> 11
A29: B.3 | B29: MUROS 1 piso
A30: B.3.3.1 | B30: Entramado Estructural | C30: R25 | E30: R21 | G30: R20 | I30: R20 | K30: R20 | M30: R20 | O30: R20 | Q30: R20 | S30: R20 | U30: R21 | W30: R21 | Y30: =COUNTIF(C30:X30,">=R") -> 11 | Z30: =Y30 -> 11
A31: B.4 | B31: ESTRUCTURA HORIZONTAL (ENTREPISO)
A32: B.4.4.1 | B32: Madera | E32: R21 | G32: R20 | I32: R20 | K32: R20 | M32: R20 | O32: R20 | Q32: R20 | S32: R20 | U32: R21 | W32: R21 | Y32: =COUNTIF(C32:X32,">=R") -> 10 | Z32: =Y32 -> 10
A33: B.4.4.2 | B33: Terciado estructural (15mm) | E33: R21 | G33: R20 | I33: R20 | K33: R20 | M33: R20 | O33: R20 | Q33: R20 | S33: R20 | U33: R21 | W33: R21 | Y33: =COUNTIF(C33:X33,">=R") -> 10 | Z33: =Y33 -> 10
A34: B.5 | B34: MUROS 2 piso
A35: B.5.3.1 | B35: Entramado Estructural (2do P) | E35: R21 | G35: R20 | I35: R20 | K35: R20 | M35: R20 | O35: R20 | Q35: R20 | S35: R20 | U35: R21 | W35: R21 | Y35: =COUNTIF(C35:X35,">=R") -> 10 | Z35: =Y35 -> 10
A36: B.6 | B36: CUBIERTA
A37: B.6.1.1 | B37: Madera | C37: R27 | E37: R21 | G37: R19 | I37: R19 | K37: R20 | M37: R19 | O37: R19 | Q37: R20 | S37: R20 | U37: R20 | W37: R21 | Y37: =COUNTIF(C37:X37,">=R") -> 11 | Z37: =Y37 -> 11
A38: B.6.2.1 | B38: Acero galvanizado (0.35mm) | C38: R27 | E38: R23 | G38: R19 | I38: R19 | K38: R23 | M38: R19 | O38: R19 | Q38: R23 | S38: R21 | U38: R21 | W38: R23 | Y38: =COUNTIF(C38:X38,">=R") -> 11 | Z38: =Y38 -> 11
A39: B.6.3 | B39: Hojalatería
A40: B.6.3.1 | B40: Canales | C40: R36 | E40: R36 | G40: R36 | I40: R36 | K40: R36 | M40: R36 | O40: R36 | Q40: R36 | S40: R36 | U40: R36 | W40: R36 | Y40: =COUNTIF(C40:X40,">=R") -> 11 | Z40: =Y40 -> 11
A41: B.6.3.2 | B41: Bajadas y Hojalaterias | Y41: =COUNTIF(C41:X41,">=R") -> 0 | Z41: =Y41 -> 0
A42: B.6.EX.1 | B42: Caballete | C42: R26 | E42: R26 | G42: R19 | I42: R19 | K42: R26 | M42: R19 | O42: R19 | Q42: R26 | S42: R26 | U42: R26 | W42: R26 | Y42: =COUNTIF(C42:X42,">=R") -> 11 | Z42: =Y42 -> 11
A43: B.6.EX.2 | B43: Esquineros | E43: R26 | G43: R20 | I43: R19 | K43: R26 | M43: R20 | O43: R20 | Q43: R26 | S43: R26 | U43: R26 | W43: R26 | Y43: =COUNTIF(C43:X43,">=R") -> 10 | Z43: =Y43 -> 10
...

Sheet MANZ.E
B1: SERVIU REGION DE LA ARAUCANIA | C1: CUADRO RESUMEN DE CONTROL RECEPCIONADO
A4: OBRA | B4: CAMPOS DEL SUR II | C4: FECHA | G4: 46037 | J4: R9 | K4: 45849 | N4: R22 | O4: 45947 | R4: R31 | S4: 46010
A5: COMUNA | B5: RENAICO | J5: R10 | K5: 45855 | N5: R23 | O5: 45954 | R5: R32 | S5: 46015
A6: CONTRATISTA | B6: CONSTRUCTORA CIMOL S.P.A | J6: R11 | K6: 45863 | N6: R24 | O6: 45960 | R6: R33 | S6: 46022
A7: RESIDENTE DE OBRA | B7: EDGAR MORALES ALARCON | J7: R12 | K7: 45870 | N7: R25 | O7: 45968 | R7: R34 | S7: 46031
A8: AUTOCONTROL | B8: MICHEL BERGER HUICHANAO | J8: R13 | K8: 45883 | N8: R26 | O8: 45975 | R8: R35 | S8: 46038
A9: E.P. | B9: PLAN SOCIAL | J9: R14 | K9: 45891 | N9: R27 | O9: 45982 | R9: R36 | S9: 46045
A10: S.A.T. | B10: OBED CEA LONCONADO | C10: VERSION | G10: 1.0 | J10: R18 | K10: 45916 | N10: R28 | O10: 45989 | R10: R37 | S10: 46052
A11: F.T.O. | B11: MAURICIO DIAZ BARRA | J11: R19 | K11: 45926 | N11: R29 | O11: 45996
A12: CODIGO | B12: 182948 | J12: R20 | K12: 45933 | N12: R30 | O12: 46003
J13: R21 | K13: 45940
A15: ITEM | B15: DESIGNACIÓN | C15: UBICACIÓN
C16: VIVIENDA LOTE Nº | AD16: MANZANA : | AJ16: E
C17: 1 | E17: 2 | G17: 3 | I17: 4 | K17: 5 | M17: 6 | O17: 7 | Q17: 8 | S17: 9 | U17: 10 | W17: 11 | Y17: 12 | AA17: 13 | AC17: 14 | AE17: 15 | AG17: 16 | AI17: 17 | AK17: T. REV | AL17: TOTAL
A18: B | B18: OBRA GRUESA | C18: AT | D18: RV | E18: AT | F18: RV | G18: AT | H18: RV | I18: AT | J18: RV | K18: AT | L18: RV | M18: AT | N18: RV | O18: AT | P18: RV | Q18: AT | R18: RV | S18: AT | T18: RV | U18: AT | V18: RV | W18: AT | X18: RV | Y18: AT | Z18: RV | AA18: AT | AB18: RV | AC18: AT | AD18: RV | AE18: AT | AF18: RV | AG18: AT | AH18: RV | AI18: AT | AJ18: RV
A19: B.1 | B19: FUNDACIONES
A20: B.1.1 | B20: Replanteo, trazado y niveles | C20: R21 | E20: R21 | G20: R21 | I20: R21 | K20: R20 | M20: R20 | O20: R20 | Q20: R20 | S20: R9 | U20: R9 | W20: R9 | Y20: R9 | AA20: R9 | AC20: R9 | AE20: R9 | AG20: R9 | AI20: R9 | AK20: =COUNTIF(C20:AJ20,">=R") -> 17 | AL20: =AK20 -> 17
A21: B.1.2 | B21: Excavación | C21: R22 | E21: R22 | G21: R21 | I21: R21 | K21: R21 | M21: R21 | O21: R21 | Q21: R21 | S21: R9 | U21: R9 | W21: R9 | Y21: R9 | AA21: R9 | AC21: R9 | AE21: R9 | AG21: R9 | AI21: R9 | AK21: =COUNTIF(C21:AJ21,">=R") -> 17 | AL21: =AK21 -> 17
A22: B.1.3 | B22: Emplantillado (G5) | C22: R22 | E22: R22 | G22: R21 | I22: R21 | K22: R21 | M22: R26 | O22: R21 | Q22: R21 | S22: R10 | U22: R10 | W22: R10 | Y22: R9 | AA22: R9 | AC22: R9 | AE22: R9 | AG22: R9 | AI22: R9 | AK22: =COUNTIF(C22:AJ22,">=R") -> 17 | AL22: =AK22 -> 17
A23: B.1.4 | B23: Hormigón cimientos (G10) | C23: R22 | E23: R22 | G23: R21 | I23: R21 | K23: R21 | M23: R26 | O23: R21 | Q23: R21 | S23: R10 | U23: R10 | W23: R10 | Y23: R9 | AA23: R9 | AC23: R9 | AE23: R9 | AG23: R9 | AI23: R9 | AK23: =COUNTIF(C23:AJ23,">=R") -> 17 | AL23: =AK23 -> 17
A24: B.1.5 | B24: Hormigón sobrecimientos (G17) | C24: R23 | E24: R23 | G24: R23 | I24: R23 | K24: R22 | M24: R22 | O24: R22 | Q24: R22 | S24: R13 | U24: R13 | W24: R13 | Y24: R13 | AA24: R13 | AC24: R13 | AE24: R13 | AG24: R13 | AI24: R13 | AK24: =COUNTIF(C24:AJ24,">=R") -> 17 | AL24: =AK24 -> 17
A25: B.1.6 | B25: Enfierradura | C25: R23 | E25: R23 | G25: R23 | I25: R23 | K25: R22 | M25: R22 | O25: R22 | Q25: R22 | S25: R13 | U25: R13 | W25: R13 | Y25: R13 | AA25: R13 | AC25: R13 | AE25: R13 | AG25: R13 | AI25: R13 | AK25: =COUNTIF(C25:AJ25,">=R") -> 17 | AL25: =AK25 -> 17
A26: B.1.7 | B26: Moldajes | C26: R23 | E26: R23 | G26: R23 | I26: R23 | K26: R22 | M26: R22 | O26: R22 | Q26: R22 | S26: R13 | U26: R13 | W26: R13 | Y26: R13 | AA26: R13 | AC26: R13 | AE26: R13 | AG26: R13 | AI26: R13 | AK26: =COUNTIF(C26:AJ26,">=R") -> 17 | AL26: =AK26 -> 17
A27: B.2 | B27: RADIER
A28: B.2.1 | B28: Base (Cama de ripio) e=0,08 mts | C28: R23 | E28: R23 | G28: R23 | I28: R23 | K28: R22 | M28: R22 | O28: R22 | Q28: R22 | S28: R13 | U28: R13 | W28: R13 | Y28: R13 | AA28: R13 | AC28: R13 | AE28: R13 | AG28: R13 | AI28: R13 | AK28: =COUNTIF(B28:AJ28,">=R") -> 17 | AL28: =AK28 -> 17
A29: B.2.2 | B29: Hormigón (G15) | C29: R23 | E29: R23 | G29: R23 | I29: R23 | K29: R22 | M29: R22 | O29: R22 | Q29: R22 | S29: R13 | U29: R13 | W29: R13 | Y29: R13 | AA29: R13 | AC29: R13 | AE29: R13 | AG29: R13 | AI29: R13 | AK29: =COUNTIF(B29:AJ29,">=R") -> 17 | AL29: =AK29 -> 17
A30: B.3 | B30: MUROS 1 piso
A31: B.3.3.1 | B31: Entramado Estructural | C31: R25 | E31: R25 | G31: R25 | I31: R25 | K31: R25 | M31: R25 | O31: R25 | Q31: R25 | S31: R21 | U31: R21 | W31: R21 | Y31: R21 | AA31: R21 | AC31: R21 | AE31: R21 | AK31: =COUNTIF(C31:AJ31,">=R") -> 15 | AL31: =AK31 -> 15
A32: B.4 | B32: ESTRUCTURA HORIZONTAL (ENTREPISO)
A33: B.4.4.1 | B33: Madera | C33: R25 | E33: R25 | G33: R25 | I33: R25 | K33: R25 | M33: R25 | O33: R25 | Q33: R25 | S33: R21 | U33: R21 | W33: R21 | Y33: R21 | AA33: R21 | AC33: R21 | AE33: R21 | AK33: =COUNTIF(C33:AJ33,">=R") -> 15 | AL33: =AK33 -> 15
A34: B.4.4.2 | B34: Terciado estructural (15mm) | C34: R27 | E34: R27 | G34: R27 | I34: R27 | K34: R25 | M34: R25 | O34: R25 | Q34: R25 | S34: R21 | U34: R21 | W34: R21 | Y34: R21 | AA34: R21 | AC34: R21 | AE34: R21 | AK34: =COUNTIF(C34:AJ34,">=R") -> 15 | AL34: =AK34 -> 15
A35: B.5 | B35: MUROS 2 piso
A36: B.5.3.1 | B36: Entramado Estructural (2do P) | C36: R31 | E36: R31 | G36: R31 | I36: R31 | K36: R31 | M36: R25 | O36: R31 | Q36: R25 | S36: R21 | U36: R21 | W36: R21 | Y36: R21 | AA36: R21 | AC36: R21 | AE36: R21 | AK36: =COUNTIF(C36:AJ36,">=R") -> 15 | AL36: =AK36 -> 15
A37: B.6 | B37: CUBIERTA
A38: B.6.1.1 | B38: Madera | C38: R31 | E38: R31 | G38: R31 | I38: R31 | K38: R31 | M38: R25 | O38: R31 | Q38: R25 | S38: R20 | U38: R20 | W38: R20 | Y38: R20 | AA38: R20 | AC38: R20 | AE38: R20 | AK38: =COUNTIF(C38:AJ38,">=R") -> 15 | AL38: =AK38 -> 15
A39: B.6.2.1 | B39: Acero galvanizado (0.35mm) | C39: R32 | E39: R32 | G39: R32 | I39: R31 | K39: R31 | M39: R25 | O39: R31 | Q39: R25 | S39: R18 | U39: R18 | W39: R18 | Y39: R18 | AA39: R18 | AC39: R18 | AE39: R18 | AK39: =COUNTIF(C39:AJ39,">=R") -> 15 | AL39: =AK39 -> 15
A40: B.6.3 | B40: Hojalatería | AK40: =COUNTIF(C40:AJ40,">=R") -> 0 | AL40: =AK40 -> 0
A41: B.6.3.1 | B41: Canales | C41: R37 | E41: R37 | G41: R37 | I41: R37 | K41: R37 | M41: R37 | O41: R37 | Q41: R37 | S41: R37 | U41: R37 | W41: R37 | Y41: R37 | AA41: R37 | AC41: R37 | AE41: R37 | AK41: =COUNTIF(C41:AJ41,">=R") -> 15 | AL41: =AK41 -> 15
A42: B.6.3.2 | B42: Bajadas y Hojalaterias | AK42: =COUNTIF(C42:AJ42,">=R") -> 0 | AL42: =AK42 -> 0
A43: B.6.EX.1 | B43: Caballete | C43: R32 | E43: R32 | G43: R32 | I43: R32 | K43: R32 | M43: R26 | O43: R32 | Q43: R18 | S43: R18 | U43: R18 | W43: R18 | Y43: R18 | AA43: R18 | AC43: R18 | AE43: R18 | AK43: =COUNTIF(C43:AJ43,">=R") -> 15 | AL43: =AK43 -> 15
...

Sheet MANZ.F
B1: SERVIU REGION DE LA ARAUCANIA | C1: CUADRO RESUMEN DE CONTROL RECEPCIONADO
A3: OBRA | B3: CAMPOS DEL SUR II | C3: FECHA | G3: 46037 | J3: R7 | K3: 45835 | N3: R16 | O3: 45905 | R3: R28 | S3: 45989 | V3: R37 | W3: 46052
A4: COMUNA | B4: RENAICO | J4: R8 | K4: 45842 | N4: R17 | O4: 45912 | R4: R29 | S4: 45996
A5: CONTRATISTA | B5: CONSTRUCTORA CIMOL S.P.A | J5: R9 | K5: 45849 | N5: R18 | O5: 45916 | R5: R30 | S5: 46003
A6: RESIDENTE DE OBRA | B6: EDGAR MORALES ALARCON | J6: R10 | K6: 45855 | N6: R21 | O6: 45940 | R6: R31 | S6: 46010
A7: AUTOCONTROL | B7: MICHEL BERGER HUICHANAO | J7: R11 | K7: 45863 | N7: R23 | O7: 45954 | R7: R32 | S7: 46015
A8: E.P. | B8: PLAN SOCIAL | J8: R12 | K8: 45870 | N8: R24 | O8: 45960 | R8: R33 | S8: 46022
A9: S.A.T. | B9: OBED CEA LONCONADO | C9: VERSION | G9: 1.0 | J9: R13 | K9: 45883 | N9: R25 | O9: 45968 | R9: R34 | S9: 46031
A10: F.T.O. | B10: MAURICIO DIAZ BARRA | J10: R14 | K10: 45891 | N10: R26 | O10: 45975 | R10: R35 | S10: 46038
A11: CODIGO | B11: 182948 | J11: R15 | K11: 45898 | N11: R27 | O11: 45982 | R11: R36 | S11: 46045
A13: ITEM | B13: DESIGNACIÓN | C13: UBICACIÓN
C14: VIVIENDA LOTE Nº | U14: MANZANA : | AA14: F
C15: 1 | E15: 2 | G15: 3 | I15: 4 | K15: 5 | M15: 6 | O15: 7 | Q15: 8 | S15: 9 | U15: 10 | W15: 11 | Y15: 12 | AA15: T. REV | AB15: TOTAL
C16: 1 | E16: 2 | G16: 3 | I16: 4 | K16: 5 | M16: 6 | O16: 7 | Q16: 8 | S16: 9 | U16: 10 | W16: 11 | Y16: 12 | AA16: T. REV | AB16: TOTAL
A17: B | B17: OBRA GRUESA | C17: AT | D17: RV | E17: AT | F17: RV | G17: AT | H17: RV | I17: AT | J17: RV | K17: AT | L17: RV | M17: AT | N17: RV | O17: AT | P17: RV | Q17: AT | R17: RV | S17: AT | T17: RV | U17: AT | V17: RV | W17: AT | X17: RV | Y17: AT | Z17: RV
A18: B.1 | B18: FUNDACIONES
A19: B.1.1 | B19: Replanteo, trazado y niveles | C19: R9 | E19: R9 | G19: R26 | I19: R7 | K19: R7 | M19: R7 | O19: R7 | Q19: R7 | S19: R7 | U19: R7 | W19: R26 | Y19: R26 | AA19: =COUNTIF(C19:Z19,">=R") -> 12 | AB19: =AA19 -> 12
A20: B.1.2 | B20: Excavación | C20: R9 | E20: R9 | G20: R7 | I20: R7 | K20: R7 | M20: R7 | O20: R7 | Q20: R7 | S20: R7 | U20: R7 | W20: R9 | Y20: R9 | AA20: =COUNTIF(C20:Z20,">=R") -> 12 | AB20: =AA20 -> 12
A21: B.1.3 | B21: Emplantillado (G5) | C21: R14 | E21: R9 | G21: R7 | I21: R7 | K21: R7 | M21: R9 | O21: R9 | Q21: R7 | S21: R7 | U21: R7 | W21: R9 | Y21: R9 | AA21: =COUNTIF(C21:Z21,">=R") -> 12 | AB21: =AA21 -> 12
A22: B.1.4 | B22: Hormigón cimientos (G10) | C22: R14 | E22: R9 | G22: R7 | I22: R7 | K22: R7 | M22: R9 | O22: R9 | Q22: R7 | S22: R7 | U22: R7 | W22: R9 | Y22: R9 | AA22: =COUNTIF(C22:Z22,">=R") -> 12 | AB22: =AA22 -> 12
A23: B.1.5 | B23: Hormigón sobrecimientos (G17) | C23: R21 | E23: R12 | G23: R13 | I23: R10 | K23: R10 | M23: R13 | O23: R13 | Q23: R10 | S23: R12 | U23: R13 | W23: R13 | Y23: R12 | AA23: =COUNTIF(C23:Z23,">=R") -> 12 | AB23: =AA23 -> 12
A24: B.1.6 | B24: Enfierradura | C24: R21 | E24: R12 | G24: R13 | I24: R10 | K24: R10 | M24: R13 | O24: R13 | Q24: R10 | S24: R12 | U24: R13 | W24: R13 | Y24: R12 | AA24: =COUNTIF(E24:Z24,">=R") -> 11 | AB24: =AA24 -> 11
A25: B.1.7 | B25: Moldajes | C25: R21 | E25: R12 | G25: R13 | I25: R10 | K25: R10 | M25: R13 | O25: R13 | Q25: R10 | S25: R12 | U25: R13 | W25: R13 | Y25: R12 | AA25: =COUNTIF(C25:Z25,">=R") -> 12 | AB25: =AA25 -> 12
A26: B.2 | B26: RADIER
A27: B.2.1 | B27: Base (Cama de ripio) e=0,08 mts | C27: R21 | E27: R12 | G27: R13 | I27: R10 | K27: R10 | M27: R13 | O27: R13 | Q27: R10 | S27: R12 | U27: R13 | W27: R13 | Y27: R12 | AA27: =COUNTIF(C27:Z27,">=R") -> 12 | AB27: =AA27 -> 12
A28: B.2.2 | B28: Hormigón (G15) | C28: R21 | E28: R12 | G28: R13 | I28: R10 | K28: R10 | M28: R13 | O28: R13 | Q28: R10 | S28: R12 | U28: R13 | W28: R13 | Y28: R12 | AA28: =COUNTIF(C28:Z28,">=R") -> 12 | AB28: =AA28 -> 12
A29: B.3 | B29: MUROS 1 piso
A30: B.3.3.1 | B30: Entramado Estructural | C30: R33 | E30: R17 | G30: R17 | I30: R17 | K30: R17 | M30: R17 | O30: R17 | Q30: R33 | S30: R17 | U30: R17 | W30: R17 | Y30: R17 | AA30: =COUNTIF(C30:Z30,">=R") -> 12 | AB30: =AA30 -> 12
A31: B.4 | B31: ESTRUCTURA HORIZONTAL (ENTREPISO)
A32: B.4.4.1 | B32: Madera | E32: R17 | G32: R17 | I32: R17 | K32: R17 | M32: R17 | O32: R17 | S32: R17 | U32: R17 | W32: R17 | Y32: R17 | AA32: =COUNTIF(C32:Z32,">=R") -> 10 | AB32: =AA32 -> 10
A33: B.4.4.2 | B33: Terciado estructural (15mm) | E33: R17 | G33: R17 | I33: R17 | K33: R17 | M33: R17 | O33: R17 | S33: R17 | U33: R17 | W33: R17 | Y33: R17 | AA33: =COUNTIF(C33:Z33,">=R") -> 10 | AB33: =AA33 -> 10
A34: B.5 | B34: MUROS 2 piso
A35: B.5.3.1 | B35: Entramado Estructural (2do P) | E35: R17 | G35: R17 | I35: R17 | K35: R17 | M35: R17 | O35: R17 | S35: R17 | U35: R17 | W35: R17 | Y35: R17 | AA35: =COUNTIF(C35:Z35,">=R") -> 10 | AB35: =AA35 -> 10
A36: B.6 | B36: CUBIERTA
A37: B.6.1.1 | B37: Madera | C37: R33 | E37: R17 | G37: R17 | I37: R17 | K37: R17 | M37: R17 | O37: R17 | Q37: R29 | S37: R17 | U37: R17 | W37: R17 | Y37: R17 | AA37: =COUNTIF(C37:Z37,">=R") -> 12 | AB37: =AA37 -> 12
A38: B.6.2.1 | B38: Acero galvanizado (0.35mm) | C38: R33 | E38: R16 | G38: R16 | I38: R16 | K38: R16 | M38: R16 | O38: R16 | Q38: R30 | S38: R16 | U38: R16 | W38: R16 | Y38: R16 | AA38: =COUNTIF(C38:Z38,">=R") -> 12 | AB38: =AA38 -> 12
A39: B.6.3 | B39: Hojalatería
A40: B.6.3.1 | B40: Canales | E40: R37 | G40: R37 | I40: R37 | K40: R37 | M40: R37 | O40: R37 | S40: R37 | U40: R37 | W40: R37 | Y40: R37 | AA40: =COUNTIF(C40:Z40,">=R") -> 10 | AB40: =AA40 -> 10
A41: B.6.3.2 | B41: Bajadas y Hojalaterias | AA41: =COUNTIF(C41:Z41,">=R") -> 0 | AB41: =AA41 -> 0
A42: B.6.EX.1 | B42: Caballete | C42: R35 | E42: R16 | G42: R16 | I42: R16 | K42: R16 | M42: R16 | O42: R16 | Q42: R30 | S42: R16 | U42: R16 | W42: R16 | Y42: R16 | AA42: =COUNTIF(C42:Z42,">=R") -> 12 | AB42: =AA42 -> 12
...

Sheet MANZ.G
B1: SERVIU REGION DE LA ARAUCANIA | C1: CUADRO RESUMEN DE CONTROL RECEPCIONADO
A7: OBRA | B7: CAMPOS DEL SUR II | C7: FECHA | G7: 46037 | J7: R2 | K7: 45797 | N7: R11 | O7: 45863 | R7: R22 | S7: 45947 | V7: R31 | W7: 46010
A8: COMUNA | B8: RENAICO | J8: R3 | K8: 45807 | N8: R12 | O8: 45870 | R8: R23 | S8: 45954 | V8: R32 | W8: 46015
A9: CONTRATISTA | B9: CONSTRUCTORA CIMOL S.P.A | J9: R4 | K9: 45814 | N9: R13 | O9: 45883 | R9: R24 | S9: 45960 | V9: R33 | W9: 46022
A10: RESIDENTE DE OBRA | B10: EDGAR MORALES ALARCON | J10: R5 | K10: 45821 | N10: R14 | O10: 45891 | R10: R25 | S10: 45968 | V10: R34 | W10: 46031
A11: AUTOCONTROL | B11: MICHEL BERGER HUICHANAO | J11: R6 | K11: 45827 | N11: R16 | O11: 45905 | R11: R26 | S11: 45975 | V11: R35 | W11: 46038
A12: E.P. | B12: PLAN SOCIAL | C12: VERSION | G12: 1.0 | J12: R7 | K12: 45835 | N12: R17 | O12: 45912 | R12: R27 | S12: 45982 | V12: R36 | W12: 46045
A13: S.A.T. | B13: OBED CEA LONCONADO | J13: R8 | K13: 45842 | N13: R19 | O13: 45926 | R13: R28 | S13: 45989 | V13: R37 | W13: 46052
A14: F.T.O. | B14: MAURICIO DIAZ BARRA | J14: R9 | K14: 45849 | N14: R20 | O14: 45933 | R14: R29 | S14: 45996
A15: CODIGO | B15: 182948 | J15: R10 | K15: 45855 | N15: R21 | O15: 45940 | R15: R30 | S15: 46003
A17: ITEM | B17: DESIGNACIÓN | C17: UBICACIÓN
C18: VIVIENDA LOTE Nº | AM18: MANZANA : | AS18: G
C19: 1 | E19: 2 | G19: 3 | I19: 4 | K19: 5 | M19: 6 | O19: 7 | Q19: 8 | S19: 9 | U19: 10 | W19: 11 | Y19: 12 | AA19: 13 | AC19: 14 | AE19: 15 | AG19: 16 | AI19: 17 | AK19: 18 | AM19: 19 | AO19: 20 | AQ19: 21 | AS19: T. REV | AT19: TOTAL
A20: B | B20: OBRA GRUESA | C20: AT | D20: RV | E20: AT | F20: RV | G20: AT | H20: RV | I20: AT | J20: RV | K20: AT | L20: RV | M20: AT | N20: RV | O20: AT | P20: RV | Q20: AT | R20: RV | S20: AT | T20: RV | U20: AT | V20: RV | W20: AT | X20: RV | Y20: AT | Z20: RV | AA20: AT | AB20: RV | AC20: AT | AD20: RV | AE20: AT | AF20: RV | AG20: AT | AH20: RV | AI20: AT | AJ20: RV | AK20: AT | AL20: RV | AM20: AT | AN20: RV | AO20: AT | AP20: RV | AQ20: AT | AR20: RV
A21: B.1 | B21: FUNDACIONES
A22: B.1.1 | B22: Replanteo, trazado y niveles | G22: R3 | I22: R3 | K22: R3 | M22: R3 | O22: R3 | Q22: R3 | S22: R3 | U22: R2 | W22: R2 | Y22: R2 | AA22: R2 | AC22: R2 | AE22: R2 | AG22: R2 | AI22: R2 | AK22: R2 | AM22: R2 | AO22: R2 | AQ22: R2 | AS22: =COUNTIF(C22:AR22,">=R") -> 19 | AT22: =AS22 -> 19
A23: B.1.2 | B23: Excavación | G23: R3 | I23: R3 | K23: R3 | M23: R3 | O23: R3 | Q23: R3 | S23: R3 | U23: R3 | W23: R2 | Y23: R2 | AA23: R2 | AC23: R2 | AE23: R2 | AG23: R2 | AI23: R2 | AK23: R2 | AM23: R2 | AO23: R2 | AQ23: R2 | AS23: =COUNTIF(C23:AR23,">=R") -> 19 | AT23: =AS23 -> 19
A24: B.1.3 | B24: Emplantillado (G5) | G24: R3 | I24: R3 | K24: R3 | M24: R3 | O24: R3 | Q24: R3 | S24: R3 | U24: R3 | W24: R2 | Y24: R2 | AA24: R2 | AC24: R2 | AE24: R2 | AG24: R2 | AI24: R2 | AK24: R2 | AM24: R2 | AO24: R2 | AQ24: R2 | AS24: =COUNTIF(C24:AR24,">=R") -> 19 | AT24: =AS24 -> 19
A25: B.1.4 | B25: Hormigón cimientos (G10) | G25: R3 | I25: R3 | K25: R3 | M25: R3 | O25: R3 | Q25: R3 | S25: R3 | U25: R3 | W25: R2 | Y25: R2 | AA25: R2 | AC25: R2 | AE25: R2 | AG25: R2 | AI25: R2 | AK25: R2 | AM25: R2 | AO25: R2 | AQ25: R2 | AS25: =COUNTIF(C25:AR25,">=R") -> 19 | AT25: =AS25 -> 19
A26: B.1.5 | B26: Hormigón sobrecimientos (G17) | G26: R4 | I26: R4 | K26: R3 | M26: R3 | O26: R3 | Q26: R3 | S26: R3 | U26: R3 | W26: R3 | Y26: R3 | AA26: R3 | AC26: R3 | AE26: R3 | AG26: R3 | AI26: R3 | AK26: R3 | AM26: R4 | AO26: R2 | AQ26: R2 | AS26: =COUNTIF(C26:AR26,">=R") -> 19 | AT26: =AS26 -> 19
A27: B.1.6 | B27: Enfierradura | G27: R4 | I27: R4 | K27: R3 | M27: R3 | O27: R3 | Q27: R3 | S27: R3 | U27: R3 | W27: R3 | Y27: R3 | AA27: R3 | AC27: R3 | AE27: R3 | AG27: R3 | AI27: R3 | AK27: R2 | AM27: R2 | AO27: R2 | AQ27: R2 | AS27: =COUNTIF(C27:AR27,">=R") -> 19 | AT27: =AS27 -> 19
A28: B.1.7 | B28: Moldajes | G28: R4 | I28: R4 | K28: R3 | M28: R3 | O28: R3 | Q28: R3 | S28: R3 | U28: R3 | W28: R3 | Y28: R3 | AA28: R3 | AC28: R3 | AE28: R3 | AG28: R3 | AI28: R3 | AK28: R2 | AM28: R2 | AO28: R2 | AQ28: R2 | AS28: =COUNTIF(C28:AR28,">=R") -> 19 | AT28: =AS28 -> 19
A29: B.2 | B29: RADIER
A30: B.2.1 | B30: Base (Cama de ripio) e=0,08 mts | G30: R4 | I30: R4 | K30: R3 | M30: R3 | O30: R3 | Q30: R3 | S30: R3 | U30: R3 | W30: R3 | Y30: R3 | AA30: R3 | AC30: R3 | AE30: R3 | AG30: R3 | AI30: R3 | AK30: R3 | AM30: R4 | AO30: R2 | AQ30: R2 | AS30: =COUNTIF(C30:AR30,">=R") -> 19 | AT30: =AS30 -> 19
A31: B.2.2 | B31: Hormigón (G15) | G31: R4 | I31: R4 | K31: R3 | M31: R3 | O31: R3 | Q31: R3 | S31: R3 | U31: R3 | W31: R3 | Y31: R3 | AA31: R3 | AC31: R3 | AE31: R3 | AG31: R3 | AI31: R3 | AK31: R3 | AM31: R4 | AO31: R2 | AQ31: R2 | AS31: =COUNTIF(C31:AR31,">=R") -> 19 | AT31: =AS31 -> 19
A32: B.3 | B32: MUROS 1 piso
A33: B.3.3.1 | B33: Entramado Estructural | I33: R6 | K33: R6 | M33: R6 | O33: R6 | Q33: R6 | S33: R6 | U33: R5 | W33: R5 | Y33: R5 | AA33: R5 | AC33: R5 | AE33: R5 | AG33: R5 | AI33: R5 | AK33: R5 | AM33: R5 | AO33: R5 | AQ33: R9 | AS33: =COUNTIF(C33:AR33,">=R") -> 18 | AT33: =AS33 -> 18
A34: B.4 | B34: ESTRUCTURA HORIZONTAL (ENTREPISO)
A35: B.4.4.1 | B35: Madera | I35: R6 | K35: R6 | M35: R6 | O35: R6 | Q35: R6 | S35: R6 | U35: R5 | W35: R5 | Y35: R5 | AA35: R5 | AC35: R5 | AE35: R5 | AG35: R5 | AI35: R5 | AK35: R5 | AM35: R5 | AO35: R5 | AQ35: R9 | AS35: =COUNTIF(C35:AR35,">=R") -> 18 | AT35: =AS35 -> 18
A36: B.4.4.2 | B36: Terciado estructural (15mm) | I36: R6 | K36: R6 | M36: R6 | O36: R6 | Q36: R6 | S36: R6 | U36: R5 | W36: R5 | Y36: R5 | AA36: R5 | AC36: R5 | AE36: R5 | AG36: R5 | AI36: R5 | AK36: R5 | AM36: R5 | AO36: R5 | AQ36: R9 | AS36: =COUNTIF(C36:AR36,">=R") -> 18 | AT36: =AS36 -> 18
A37: B.5 | B37: MUROS 2 piso
A38: B.5.3.1 | B38: Entramado Estructural (2do P) | I38: R6 | K38: R6 | M38: R6 | O38: R6 | Q38: R6 | S38: R6 | U38: R5 | W38: R5 | Y38: R5 | AA38: R5 | AC38: R5 | AE38: R5 | AG38: R5 | AI38: R5 | AK38: R5 | AM38: R5 | AO38: R5 | AQ38: R9 | AS38: =COUNTIF(C38:AR38,">=R") -> 18 | AT38: =AS38 -> 18
A39: B.6 | B39: CUBIERTA
A40: B.6.1.1 | B40: Madera | I40: R7 | K40: R7 | M40: R7 | O40: R7 | Q40: R7 | S40: R6 | U40: R6 | W40: R6 | Y40: R6 | AA40: R5 | AC40: R5 | AE40: R5 | AG40: R5 | AI40: R5 | AK40: R5 | AM40: R5 | AO40: R5 | AQ40: R9 | AS40: =COUNTIF(C40:AR40,">=R") -> 18 | AT40: =AS40 -> 18
A41: B.6.2.1 | B41: Acero galvanizado (0.35mm) | I41: R7 | K41: R7 | M41: R7 | O41: R7 | Q41: R7 | S41: R7 | U41: R7 | W41: R7 | Y41: R7 | AA41: R7 | AC41: R7 | AE41: R9 | AG41: R9 | AI41: R9 | AK41: R9 | AM41: R9 | AO41: R5 | AQ41: R11 | AS41: =COUNTIF(C41:AR41,">=R") -> 18 | AT41: =AS41 -> 18
A42: B.6.3 | B42: Hojalatería
A43: B.6.3.1 | B43: Canales | I43: R36 | K43: R36 | M43: R36 | O43: R36 | Q43: R36 | S43: R36 | U43: R36 | W43: R36 | Y43: R36 | AA43: R36 | AC43: R36 | AE43: R36 | AG43: R36 | AI43: R36 | AK43: R36 | AM43: R36 | AO43: R10 | AQ43: R36 | AS43: =COUNTIF(C43:AR43,">=R") -> 18 | AT43: =AS43 -> 18
A44: B.6.3.2 | B44: Bajadas y Hojalaterias | AS44: =COUNTIF(C44:AR44,">=R") -> 0 | AT44: =AS44 -> 0
A45: B.6.EX.1 | B45: Caballete | I45: R9 | K45: R9 | M45: R26 | O45: R26 | Q45: R26 | S45: R9 | U45: R9 | W45: R9 | Y45: R9 | AA45: R9 | AC45: R9 | AE45: R9 | AG45: R9 | AI45: R9 | AK45: R9 | AM45: R9 | AO45: R5 | AQ45: R21 | AS45: =COUNTIF(C45:AR45,">=R") -> 18 | AT45: =AS45 -> 18
A46: B.6.EX.2 | B46: Esquineros | I46: R15 | K46: R24 | M46: R15 | O46: R24 | Q46: R24 | S46: R15 | U46: R15 | W46: R24 | Y46: R24 | AA46: R24 | AC46: R24 | AE46: R15 | AG46: R15 | AI46: R7 | AK46: R7 | AM46: R7 | AO46: R7 | AQ46: R15 | AS46: =COUNTIF(C46:AR46,">=R") -> 18 | AT46: =AS46 -> 18
...

Sheet MANZ.H
B1: SERVIU REGION DE LA ARAUCANIA | C1: CUADRO RESUMEN DE CONTROL RECEPCIONADO
A4: OBRA | B4: CAMPOS DEL SUR II | C4: FECHA | G4: 46037 | J4: R4 | K4: 45814 | N4: R15 | O4: 45898 | R4: R29 | S4: 45996
A5: COMUNA | B5: RENAICO | J5: R5 | K5: 45821 | N5: R16 | O5: 45905 | R5: R30 | S5: 46003
A6: CONTRATISTA | B6: CONSTRUCTORA CIMOL S.P.A | J6: R7 | K6: 45835 | N6: R20 | O6: 45933 | R6: R31 | S6: 46010
A7: RESIDENTE DE OBRA | B7: EDGAR MORALES ALARCON | J7: R8 | K7: 45842 | N7: R21 | O7: 45940 | R7: R32 | S7: 46015
A8: AUTOCONTROL | B8: MICHEL BERGER HUICHANAO | J8: R9 | K8: 45849 | N8: R23 | O8: 45954 | R8: R33 | S8: 46022
A9: E.P. | B9: PLAN SOCIAL | J9: R10 | K9: 45855 | N9: R24 | O9: 45960 | R9: R34 | S9: 46031
A10: S.A.T. | B10: OBED CEA LONCONADO | C10: VERSION | G10: 1.0 | J10: R11 | K10: 45863 | N10: R25 | O10: 45968 | R10: R35 | S10: 46038
A11: F.T.O. | B11: MAURICIO DIAZ BARRA | J11: R12 | K11: 45870 | N11: R26 | O11: 45975 | R11: R36 | S11: 46045
A12: CODIGO | B12: 182948 | J12: R13 | K12: 45883 | N12: R27 | O12: 45982 | R12: R37 | S12: 46052
J13: R14 | K13: 45891 | N13: R28 | O13: 45989
A15: ITEM | B15: DESIGNACIÓN | C15: UBICACIÓN
C16: VIVIENDA LOTE Nº | O16: MANZANA : | U16: H
C17: 1 | E17: 2 | G17: 3 | I17: 4 | K17: 5 | M17: 6 | O17: 7 | Q17: 8 | S17: 9 | U17: T. REV | V17: TOTAL
A18: B | B18: OBRA GRUESA | C18: AT | D18: RV | E18: AT | F18: RV | G18: AT | H18: RV | I18: AT | J18: RV | K18: AT | L18: RV | M18: AT | N18: RV | O18: AT | P18: RV | Q18: AT | R18: RV | S18: AT | T18: RV
A19: B.1 | B19: FUNDACIONES
A20: B.1.1 | B20: Replanteo, trazado y niveles | C20: R4 | E20: R4 | G20: R4 | I20: R4 | K20: R4 | M20: R4 | O20: R4 | Q20: R4 | S20: R4 | U20: =COUNTIF(C20:T20,">=R") -> 9 | V20: =U20 -> 9
A21: B.1.2 | B21: Excavación | C21: R5 | E21: R5 | G21: R5 | I21: R5 | K21: R4 | M21: R4 | O21: R4 | Q21: R4 | S21: R4 | U21: =COUNTIF(C21:T21,">=R") -> 9 | V21: =U21 -> 9
A22: B.1.3 | B22: Emplantillado (G5) | C22: R5 | E22: R5 | G22: R5 | I22: R5 | K22: R5 | M22: R5 | O22: R5 | Q22: R5 | S22: R5 | U22: =COUNTIF(C22:T22,">=R") -> 9 | V22: =U22 -> 9
A23: B.1.4 | B23: Hormigón cimientos (G10) | C23: R5 | E23: R5 | G23: R5 | I23: R5 | K23: R5 | M23: R5 | O23: R5 | Q23: R5 | S23: R5 | U23: =COUNTIF(C23:T23,">=R") -> 9 | V23: =U23 -> 9
A24: B.1.5 | B24: Hormigón sobrecimientos (G17) | C24: R7 | E24: R7 | G24: R7 | I24: R7 | K24: R5 | M24: R5 | O24: R5 | Q24: R7 | S24: R7 | U24: =COUNTIF(C24:T24,">=R") -> 9 | V24: =U24 -> 9
A25: B.1.6 | B25: Enfierradura | C25: R7 | E25: R7 | G25: R7 | I25: R7 | K25: R5 | M25: R5 | O25: R5 | Q25: R7 | S25: R7 | U25: =COUNTIF(C25:T25,">=R") -> 9 | V25: =U25 -> 9
A26: B.1.7 | B26: Moldajes | C26: R7 | E26: R7 | G26: R7 | I26: R7 | K26: R5 | M26: R5 | O26: R5 | Q26: R7 | S26: R7 | U26: =COUNTIF(C26:T26,">=R") -> 9 | V26: =U26 -> 9
A27: B.2 | B27: RADIER
A28: B.2.1 | B28: Base (Cama de ripio) e=0,08 mts | C28: R8 | E28: R8 | G28: R8 | I28: R7 | K28: R6 | M28: R6 | O28: R6 | Q28: R7 | S28: R7 | U28: =COUNTIF(C28:T28,">=R") -> 9 | V28: =U28 -> 9
A29: B.2.2 | B29: Hormigón (G15) | C29: R8 | E29: R8 | G29: R8 | I29: R7 | K29: R6 | M29: R6 | O29: R6 | Q29: R7 | S29: R7 | U29: =COUNTIF(C29:T29,">=R") -> 9 | V29: =U29 -> 9
A30: B.3 | B30: MUROS 1 piso
A31: B.3.3.1 | B31: Entramado Estructural | C31: R12 | E31: R12 | G31: R12 | I31: R12 | K31: R11 | M31: R11 | O31: R11 | Q31: R11 | S31: R11 | U31: =COUNTIF(C31:T31,">=R") -> 9 | V31: =U31 -> 9
A32: B.4 | B32: ESTRUCTURA HORIZONTAL (ENTREPISO)
A33: B.4.4.1 | B33: Madera | C33: R12 | E33: R12 | G33: R12 | I33: R12 | K33: R11 | M33: R11 | O33: R11 | Q33: R11 | S33: R11 | U33: =COUNTIF(C33:T33,">=R") -> 9 | V33: =U33 -> 9
A34: B.4.4.2 | B34: Terciado estructural (15mm) | C34: R12 | E34: R12 | G34: R12 | I34: R12 | K34: R11 | M34: R11 | O34: R11 | Q34: R11 | S34: R11 | U34: =COUNTIF(C34:T34,">=R") -> 9 | V34: =U34 -> 9
A35: B.5 | B35: MUROS 2 piso
A36: B.5.3.1 | B36: Entramado Estructural (2do P) | C36: R12 | E36: R12 | G36: R12 | I36: R12 | K36: R11 | M36: R11 | O36: R11 | Q36: R11 | S36: R11 | U36: =COUNTIF(C36:T36,">=R") -> 9 | V36: =U36 -> 9
A37: B.6 | B37: CUBIERTA
A38: B.6.1.1 | B38: Madera | C38: R12 | E38: R12 | G38: R12 | I38: R12 | K38: R26 | M38: R26 | O38: R26 | Q38: R11 | S38: R11 | U38: =COUNTIF(C38:T38,">=R") -> 9 | V38: =U38 -> 9
A39: B.6.2.1 | B39: Acero galvanizado (0.35mm) | C39: R12 | E39: R12 | G39: R12 | I39: R12 | K39: R26 | M39: R26 | O39: R26 | Q39: R11 | S39: R11 | U39: =COUNTIF(C39:T39,">=R") -> 9 | V39: =U39 -> 9
A40: B.6.3 | B40: Hojalatería
A41: B.6.3.1 | B41: Canales | U41: =COUNTIF(C41:T41,">=R") -> 0 | V41: =U41 -> 0
A42: B.6.3.2 | B42: Bajadas y Hojalaterias | U42: =COUNTIF(C42:T42,">=R") -> 0 | V42: =U42 -> 0
A43: B.6.EX.1 | B43: Caballete | C43: R12 | E43: R12 | G43: R12 | I43: R12 | K43: R12 | M43: R12 | O43: R12 | Q43: R12 | S43: R12 | U43: =COUNTIF(C43:T43,">=R") -> 9 | V43: =U43 -> 9
...

Sheet MANZ.I
B1: SERVIU REGION DE LA ARAUCANIA | C1: CUADRO RESUMEN DE CONTROL RECEPCIONADO
A4: OBRA | B4: CAMPOS DEL SUR II | C4: FECHA | G4: 46037 | J4: R4 | K4: 45814 | N4: R14 | O4: 45891 | R4: R25 | S4: 45968 | V4: R35 | W4: 46038
A5: COMUNA | B5: RENAICO | J5: R5 | K5: 45821 | N5: R15 | O5: 45898 | R5: R26 | S5: 45975 | V5: R36 | W5: 46045
A6: CONTRATISTA | B6: CONSTRUCTORA CIMOL S.P.A | J6: R6 | K6: 45827 | N6: R16 | O6: 45905 | R6: R27 | S6: 45982 | V6: R37 | W6: 46052
A7: RESIDENTE DE OBRA | B7: EDGAR MORALES ALARCON | J7: R7 | K7: 45835 | N7: R17 | O7: 45912 | R7: R28 | S7: 45989
A8: AUTOCONTROL | B8: MICHEL BERGER HUICHANAO | J8: R8 | K8: 45842 | N8: R18 | O8: 45916 | R8: R29 | S8: 45996
A9: E.P. | B9: PLAN SOCIAL | J9: R9 | K9: 45849 | N9: R20 | O9: 45933 | R9: R30 | S9: 46003
A10: S.A.T. | B10: OBED CEA LONCONADO | C10: VERSION | G10: 1.0 | J10: R10 | K10: 45855 | N10: R21 | O10: 45940 | R10: R31 | S10: 46010
A11: F.T.O. | B11: MAURICIO DIAZ BARRA | J11: R11 | K11: 45863 | N11: R22 | O11: 45947 | R11: R32 | S11: 46015
A12: CODIGO | B12: 182948 | J12: R12 | K12: 45870 | N12: R23 | O12: 45954 | R12: R33 | S12: 46022
J13: R13 | K13: 45883 | N13: R24 | O13: 45960 | R13: R34 | S13: 46031
A15: ITEM | B15: DESIGNACIÓN | C15: UBICACIÓN
C16: VIVIENDA LOTE Nº | U16: MANZANA : | AA16: I
C17: 1 | E17: 2 | G17: 3 | I17: 4 | K17: 5 | M17: 6 | O17: 7 | Q17: 8 | S17: 9 | U17: 10 | W17: 11 | Y17: 12 | AA17: T. REV | AB17: TOTAL
A18: B | B18: OBRA GRUESA | C18: AT | D18: RV | E18: AT | F18: RV | G18: AT | H18: RV | I18: AT | J18: RV | K18: AT | L18: RV | M18: AT | N18: RV | O18: AT | P18: RV | Q18: AT | R18: RV | S18: AT | T18: RV | U18: AT | V18: RV | W18: AT | X18: RV | Y18: AT | Z18: RV
A19: B.1 | B19: FUNDACIONES
A20: B.1.1 | B20: Replanteo, trazado y niveles | C20: R5 | E20: R5 | G20: R5 | I20: R5 | K20: R4 | M20: R4 | O20: R4 | Q20: R5 | S20: R5 | U20: R5 | W20: R5 | Y20: R5 | AA20: =COUNTIF(C20:Z20,">=R") -> 12 | AB20: =AA20 -> 12
A21: B.1.2 | B21: Excavación | C21: R6 | E21: R6 | G21: R26 | I21: R26 | K21: R4 | M21: R4 | O21: R4 | Q21: R25 | S21: R5 | U21: R5 | W21: R5 | Y21: R5 | AA21: =COUNTIF(C21:Z21,">=R") -> 12 | AB21: =AA21 -> 12
A22: B.1.3 | B22: Emplantillado (G5) | C22: R6 | E22: R6 | G22: R7 | I22: R7 | K22: R5 | M22: R5 | O22: R5 | Q22: R25 | S22: R6 | U22: R6 | W22: R6 | Y22: R6 | AA22: =COUNTIF(C22:Z22,">=R") -> 12 | AB22: =AA22 -> 12
A23: B.1.4 | B23: Hormigón cimientos (G10) | C23: R6 | E23: R6 | G23: R7 | I23: R7 | K23: R5 | M23: R5 | O23: R5 | Q23: R26 | S23: R6 | U23: R6 | W23: R6 | Y23: R6 | AA23: =COUNTIF(C23:Z23,">=R") -> 12 | AB23: =AA23 -> 12
A24: B.1.5 | B24: Hormigón sobrecimientos (G17) | C24: R8 | E24: R8 | G24: R9 | I24: R9 | K24: R5 | M24: R5 | O24: R7 | Q24: R16 | S24: R9 | U24: R8 | W24: R11 | Y24: R11 | AA24: =COUNTIF(C24:Z24,">=R") -> 12 | AB24: =AA24 -> 12
A25: B.1.6 | B25: Enfierradura | C25: R8 | E25: R8 | G25: R9 | I25: R9 | K25: R5 | M25: R5 | O25: R7 | Q25: R16 | S25: R9 | U25: R8 | W25: R7 | Y25: R7 | AA25: =COUNTIF(C25:Z25,">=R") -> 12 | AB25: =AA25 -> 12
A26: B.1.7 | B26: Moldajes | C26: R8 | E26: R8 | G26: R9 | I26: R9 | K26: R5 | M26: R5 | O26: R7 | Q26: R16 | S26: R9 | U26: R8 | W26: R7 | Y26: R7 | AA26: =COUNTIF(C26:Z26,">=R") -> 12 | AB26: =AA26 -> 12
A27: B.2 | B27: RADIER
A28: B.2.1 | B28: Base (Cama de ripio) e=0,08 mts | C28: R8 | E28: R8 | G28: R9 | I28: R9 | K28: R5 | M28: R5 | O28: R8 | Q28: R16 | S28: R9 | U28: R8 | W28: R8 | Y28: R8 | AA28: =COUNTIF(C28:Z28,">=R") -> 12 | AB28: =AA28 -> 12
A29: B.2.2 | B29: Hormigón (G15) | C29: R8 | E29: R8 | G29: R9 | I29: R9 | K29: R5 | M29: R5 | O29: R8 | Q29: R16 | S29: R9 | U29: R8 | W29: R8 | Y29: R8 | AA29: =COUNTIF(C29:Z29,">=R") -> 12 | AB29: =AA29 -> 12
A30: B.3 | B30: MUROS 1 piso
A31: B.3.3.1 | B31: Entramado Estructural | C31: R25 | E31: R15 | G31: R15 | I31: R15 | K31: R11 | M31: R11 | O31: R11 | Q31: R26 | S31: R15 | U31: R15 | W31: R15 | Y31: R15 | AA31: =COUNTIF(C31:Z31,">=R") -> 12 | AB31: =AA31 -> 12
A32: B.4 | B32: ESTRUCTURA HORIZONTAL (ENTREPISO)
A33: B.4.4.1 | B33: Madera | E33: R15 | G33: R15 | I33: R15 | K33: R11 | M33: R11 | O33: R11 | S33: R15 | U33: R15 | W33: R15 | Y33: R15 | AA33: =COUNTIF(C33:Z33,">=R") -> 10 | AB33: =AA33 -> 10
A34: B.4.4.2 | B34: Terciado estructural (15mm) | E34: R15 | G34: R15 | I34: R15 | K34: R11 | M34: R11 | O34: R11 | S34: R15 | U34: R15 | W34: R15 | Y34: R15 | AA34: =COUNTIF(C34:Z34,">=R") -> 10 | AB34: =AA34 -> 10
A35: B.5 | B35: MUROS 2 piso
A36: B.5.3.1 | B36: Entramado Estructural (2do P) | E36: R15 | G36: R15 | I36: R15 | K36: R11 | M36: R11 | O36: R11 | S36: R15 | U36: R15 | W36: R15 | Y36: R15 | AA36: =COUNTIF(C36:Z36,">=R") -> 10 | AB36: =AA36 -> 10
A37: B.6 | B37: CUBIERTA
A38: B.6.1.1 | B38: Madera | C38: R29 | E38: R15 | G38: R15 | I38: R15 | K38: R11 | M38: R11 | O38: R11 | Q38: R29 | S38: R15 | U38: R15 | W38: R15 | Y38: R15 | AA38: =COUNTIF(C38:Z38,">=R") -> 12 | AB38: =AA38 -> 12
A39: B.6.2.1 | B39: Acero galvanizado (0.35mm) | C39: R31 | E39: R15 | G39: R15 | I39: R15 | K39: R10 | M39: R10 | O39: R10 | Q39: R34 | S39: R15 | U39: R15 | W39: R12 | Y39: R12 | AA39: =COUNTIF(C39:Z39,">=R") -> 12 | AB39: =AA39 -> 12
A40: B.6.3 | B40: Hojalatería
A41: B.6.3.1 | B41: Canales | AA41: =COUNTIF(C41:Z41,">=R") -> 0 | AB41: =AA41 -> 0
A42: B.6.3.2 | B42: Bajadas y Hojalaterias | AA42: =COUNTIF(C42:Z42,">=R") -> 0 | AB42: =AA42 -> 0
A43: B.6.EX.1 | B43: Caballete | K43: R10 | M43: R10 | O43: R10 | Q43: R34 | AA43: =COUNTIF(C43:Z43,">=R") -> 4 | AB43: =AA43 -> 4
...

Sheet MANZ.J
B3: SERVIU REGION DE LA ARAUCANIA | C3: CUADRO RESUMEN DE CONTROL RECEPCIONADO
B6: SERVIU REGION DE LA ARAUCANIA | C6: CUADRO RESUMEN DE CONTROL RECEPCIONADO
A9: OBRA | B9: CAMPOS DEL SUR II | C9: FECHA | G9: 46037 | J9: R14 | K9: 45891 | N9: R22 | O9: 45947 | R9: R31 | S9: 46010
A10: COMUNA | B10: RENAICO | J10: R15 | K10: 45898 | N10: R23 | O10: 45954 | R10: R32 | S10: 46015
A11: CONTRATISTA | B11: CONSTRUCTORA CIMOL S.P.A | J11: R16 | K11: 45905 | N11: R24 | O11: 45960 | R11: R33 | S11: 46022
A12: RESIDENTE DE OBRA | B12: EDGAR MORALES ALARCON | J12: R17 | K12: 45912 | N12: R25 | O12: 45968 | R12: R34 | S12: 46031
A13: AUTOCONTROL | B13: MICHEL BERGER HUICHANAO | J13: R18 | K13: 45916 | N13: R26 | O13: 45975 | R13: R35 | S13: 46038
A14: E.P. | B14: PLAN SOCIAL | J14: R19 | K14: 45926 | N14: R27 | O14: 45982 | R14: R36 | S14: 46045
A15: S.A.T. | B15: OBED CEA LONCONADO | J15: R20 | K15: 45933 | N15: R28 | O15: 45989 | R15: R37 | S15: 46052
A16: F.T.O. | B16: MAURICIO DIAZ BARRA | J16: R21 | K16: 45939 | N16: R29 | O16: 45996
A17: CODIGO | B17: 182948 | N17: R30 | O17: 46003
A18: ITEM | B18: DESIGNACIÓN | C18: UBICACIÓN
C19: VIVIENDA LOTE Nº | AD19: MANZANA : | AJ19: J
C20: 1 | E20: 2 | G20: 3 | I20: 4 | K20: 5 | M20: 6 | O20: 7 | Q20: 8 | S20: 9 | U20: 10 | W20: 11 | Y20: 12 | AA20: 13 | AC20: 14 | AE20: 15 | AG20: 16 | AI20: 17 | AK20: 18 | AM20: 19 | AO20: 20 | AQ20: 21 | AS20: T. REV | AT20: TOTAL
A21: B | B21: OBRA GRUESA | C21: AT | D21: RV | E21: AT | F21: RV | G21: AT | H21: RV | I21: AT | J21: RV | K21: AT | L21: RV | M21: AT | N21: RV | O21: AT | P21: RV | Q21: AT | R21: RV | S21: AT | T21: RV | U21: AT | V21: RV | W21: AT | X21: RV | Y21: AT | Z21: RV | AA21: AT | AB21: RV | AC21: AT | AD21: RV | AE21: AT | AF21: RV | AG21: AT | AH21: RV | AI21: AT | AJ21: RV | AK21: AT | AL21: RV | AM21: AT | AN21: RV | AO21: AT | AP21: RV | AQ21: AT | AR21: RV
A22: B.1 | B22: FUNDACIONES
A23: B.1.1 | B23: Replanteo, trazado y niveles | C23: R17 | E23: R17 | G23: R17 | I23: R17 | K23: R17 | M23: R17 | O23: R17 | Q23: R17 | S23: R17 | U23: R18 | W23: R18 | Y23: R18 | AA23: R18 | AC23: R21 | AE23: R21 | AG23: R21 | AI23: R25 | AK23: R14 | AM23: R14 | AO23: R14 | AQ23: R14 | AS23: =COUNTIF(C23:AR23,">=R") -> 21 | AT23: =AS23 -> 21
A24: B.1.2 | B24: Excavación | C24: R17 | E24: R17 | G24: R17 | I24: R17 | K24: R18 | M24: R18 | O24: R18 | Q24: R19 | S24: R19 | U24: R19 | W24: R20 | Y24: R20 | AA24: R20 | AC24: R21 | AE24: R21 | AG24: R21 | AI24: R25 | AK24: R14 | AM24: R14 | AO24: R14 | AQ24: R14 | AS24: =COUNTIF(C24:AR24,">=R") -> 21 | AT24: =AS24 -> 21
A25: B.1.3 | B25: Emplantillado (G5) | C25: R17 | E25: R17 | G25: R17 | I25: R19 | K25: R19 | M25: R19 | O25: R19 | Q25: R19 | S25: R19 | U25: R19 | W25: R20 | Y25: R20 | AA25: R20 | AC25: R21 | AE25: R21 | AG25: R21 | AI25: R25 | AK25: R26 | AM25: R26 | AO25: R15 | AQ25: R15 | AS25: =COUNTIF(C25:AR25,">=R") -> 21 | AT25: =AS25 -> 21
A26: B.1.4 | B26: Hormigón cimientos (G10) | C26: R17 | E26: R17 | G26: R17 | I26: R19 | K26: R19 | M26: R19 | O26: R19 | Q26: R19 | S26: R19 | U26: R19 | W26: R20 | Y26: R20 | AA26: R20 | AC26: R21 | AE26: R21 | AG26: R21 | AI26: R25 | AK26: R26 | AM26: R26 | AO26: R15 | AQ26: R15 | AS26: =COUNTIF(C26:AR26,">=R") -> 21 | AT26: =AS26 -> 21
A27: B.1.5 | B27: Hormigón sobrecimientos (G17) | C27: R19 | E27: R19 | G27: R19 | I27: R19 | K27: R20 | M27: R20 | O27: R20 | Q27: R20 | S27: R20 | U27: R20 | W27: R20 | Y27: R21 | AA27: R21 | AC27: R21 | AE27: R26 | AG27: R23 | AI27: R23 | AK27: R21 | AM27: R16 | AO27: R16 | AQ27: R16 | AS27: =COUNTIF(C27:AR27,">=R") -> 21 | AT27: =AS27 -> 21
A28: B.1.6 | B28: Enfierradura | C28: R19 | E28: R19 | G28: R19 | I28: R19 | K28: R20 | M28: R20 | O28: R20 | Q28: R20 | S28: R20 | U28: R20 | W28: R20 | Y28: R21 | AA28: R21 | AC28: R21 | AE28: R26 | AG28: R23 | AI28: R23 | AK28: R21 | AM28: R16 | AO28: R16 | AQ28: R16 | AS28: =COUNTIF(C28:AR28,">=R") -> 21 | AT28: =AS28 -> 21
A29: B.1.7 | B29: Moldajes | C29: R19 | E29: R19 | G29: R19 | I29: R19 | K29: R20 | M29: R20 | O29: R20 | Q29: R20 | S29: R20 | U29: R20 | W29: R20 | Y29: R21 | AA29: R21 | AC29: R21 | AE29: R26 | AG29: R23 | AI29: R23 | AK29: R21 | AM29: R16 | AO29: R16 | AQ29: R16 | AS29: =COUNTIF(C29:AR29,">=R") -> 21 | AT29: =AS29 -> 21
A30: B.2 | B30: RADIER
A31: B.2.1 | B31: Base (Cama de ripio) e=0,08 mts | C31: R19 | E31: R19 | G31: R19 | I31: R19 | K31: R20 | M31: R20 | O31: R20 | Q31: R20 | S31: R20 | U31: R20 | W31: R20 | Y31: R21 | AA31: R21 | AC31: R21 | AE31: R26 | AG31: R23 | AI31: R23 | AK31: R21 | AM31: R16 | AO31: R16 | AQ31: R16 | AS31: =COUNTIF(C31:AR31,">=R") -> 21 | AT31: =AS31 -> 21
A32: B.2.2 | B32: Hormigón (G15) | C32: R19 | E32: R19 | G32: R19 | I32: R19 | K32: R20 | M32: R20 | O32: R20 | Q32: R20 | S32: R20 | U32: R20 | W32: R20 | Y32: R21 | AA32: R21 | AC32: R21 | AE32: R26 | AG32: R23 | AI32: R23 | AK32: R21 | AM32: R16 | AO32: R16 | AQ32: R16 | AS32: =COUNTIF(C32:AR32,">=R") -> 21 | AT32: =AS32 -> 21
A33: B.3 | B33: MUROS 1 piso
A34: B.3.3.1 | B34: Entramado Estructural | C34: R21 | E34: R21 | G34: R21 | I34: R21 | K34: R24 | M34: R24 | O34: R24 | Q34: R24 | S34: R24 | U34: R24 | W34: R24 | Y34: R24 | AA34: R24 | AC34: R24 | AE34: R30 | AG34: R30 | AI34: R29 | AK34: R30 | AM34: R21 | AO34: R21 | AQ34: R21 | AS34: =COUNTIF(C34:AR34,">=R") -> 21 | AT34: =AS34 -> 21
A35: B.4 | B35: ESTRUCTURA HORIZONTAL (ENTREPISO)
A36: B.4.4.1 | B36: Madera | C36: R21 | E36: R21 | G36: R21 | I36: R21 | K36: R24 | M36: R24 | O36: R24 | Q36: R24 | S36: R24 | U36: R24 | W36: R24 | Y36: R24 | AA36: R24 | AC36: R24 | AE36: R30 | AG36: R30 | AK36: R30 | AM36: R21 | AO36: R21 | AQ36: R21 | AS36: =COUNTIF(C36:AR36,">=R") -> 19 | AT36: =AS36 -> 19
A37: B.4.4.2 | B37: Terciado estructural (15mm) | C37: R21 | E37: R21 | G37: R21 | I37: R21 | K37: R24 | M37: R24 | O37: R24 | Q37: R24 | S37: R24 | U37: R24 | W37: R24 | Y37: R24 | AA37: R24 | AC37: R24 | AE37: R30 | AG37: R30 | AK37: R30 | AM37: R21 | AO37: R21 | AQ37: R21 | AS37: =COUNTIF(C37:AR37,">=R") -> 19 | AT37: =AS37 -> 19
A38: B.5 | B38: MUROS 2 piso
A39: B.5.3.1 | B39: Entramado Estructural (2do P) | C39: R21 | E39: R21 | G39: R21 | I39: R21 | K39: R24 | M39: R24 | O39: R24 | Q39: R24 | S39: R24 | U39: R24 | W39: R24 | Y39: R24 | AA39: R24 | AC39: R24 | AE39: R30 | AG39: R30 | AK39: R30 | AM39: R21 | AO39: R21 | AQ39: R21 | AS39: =COUNTIF(C39:AR39,">=R") -> 19 | AT39: =AS39 -> 19
A40: B.6 | B40: CUBIERTA
A41: B.6.1.1 | B41: Madera | C41: R21 | E41: R21 | G41: R21 | I41: R21 | K41: R24 | M41: R24 | O41: R24 | Q41: R24 | S41: R24 | U41: R24 | W41: R24 | Y41: R24 | AA41: R24 | AC41: R24 | AE41: R29 | AG41: R29 | AK41: R29 | AM41: R21 | AO41: R21 | AQ41: R21+ | AS41: =COUNTIF(C41:AR41,">=R") -> 20 | AT41: =AS41 -> 20
A42: B.6.2.1 | B42: Acero galvanizado (0.35mm) | C42: R21 | E42: R21 | G42: R21 | I42: R21 | K42: R25 | M42: R25 | O42: R25 | Q42: R25 | S42: R24 | U42: R24 | W42: R24 | Y42: R24 | AA42: R24 | AC42: R24 | AE42: R29 | AG42: R29 | AK42: R28 | AM42: R26 | AO42: R26 | AQ42: R26 | AS42: =COUNTIF(C42:AR42,">=R") -> 20 | AT42: =AS42 -> 20
A43: B.6.3 | B43: Hojalatería
A44: B.6.3.1 | B44: Canales | AS44: =COUNTIF(C44:AR44,">=R") -> 0 | AT44: =AS44 -> 0
A45: B.6.3.2 | B45: Bajadas y Hojalaterias | AS45: =COUNTIF(C45:AR45,">=R") -> 0 | AT45: =AS45 -> 0
A46: B.6.EX.1 | B46: Caballete | C46: R24 | E46: R24 | G46: R24 | I46: R24 | K46: R24 | M46: R24 | O46: R24 | Q46: R24 | S46: R24 | U46: R24 | W46: R26 | Y46: R26 | AA46: R27 | AC46: R27 | AE46: R29 | AG46: R29 | AK46: R32 | AM46: R21 | AO46: R21 | AQ46: R21 | AS46: =COUNTIF(C46:AR46,">=R") -> 20 | AT46: =AS46 -> 20
...

Sheet MANZ.K
B1: SERVIU REGION DE LA ARAUCANIA | C1: CUADRO RESUMEN DE CONTROL RECEPCIONADO | AC1: CUADRO RESUMEN DE CONTROL RECEPCIONADO
A4: OBRA | B4: CAMPOS DEL SUR II | C4: FECHA | G4: 46037 | J4: R4 | K4: 45814 | N4: R10 | O4: 45855 | R4: R16 | S4: 45905 | V4: R24 | W4: 45960 | Z4: R30 | AA4: 46003 | AD4: R37 | AE4: 46052
A5: COMUNA | B5: RENAICO | J5: R5 | K5: 45821 | N5: R11 | O5: 45863 | R5: R17 | S5: 45912 | V5: R25 | W5: 45968 | Z5: R31 | AA5: 46010
A6: CONTRATISTA | B6: CONSTRUCTORA CIMOL S.P.A | J6: R6 | K6: 46192 | N6: R12 | O6: 45870 | R6: R19 | S6: 45926 | V6: R26 | W6: 45975 | Z6: R32 | AA6: 46015
A7: RESIDENTE DE OBRA | B7: EDGAR MORALES ALARCON | J7: R7 | K7: 45835 | N7: R13 | O7: 45883 | R7: R21 | S7: 45940 | V7: R27 | W7: 45982 | Z7: R33 | AA7: 46022
A8: AUTOCONTROL | B8: MICHEL BERGER HUICHANAO | J8: R8 | K8: 45842 | N8: R14 | O8: 45891 | R8: R22 | S8: 45947 | V8: R28 | W8: 45989 | Z8: R34 | AA8: 46031
A9: E.P. | B9: PLAN SOCIAL | J9: R9 | K9: 45849 | N9: R15 | O9: 45898 | R9: R23 | S9: 45954 | V9: R29 | W9: 45996 | Z9: R35 | AA9: 46038
A10: S.A.T. | B10: OBED CEA LONCONADO | C10: VERSION | G10: 1.0
A11: F.T.O. | B11: MAURICIO DIAZ BARRA
A12: CODIGO | B12: 182948
A15: ITEM | B15: DESIGNACIÓN | C15: UBICACIÓN
C16: VIVIENDA LOTE Nº | U16: MANZANA : | AA16: K
C17: 1 | E17: 2 | G17: 3 | I17: 4 | K17: 5 | M17: 6 | O17: 7 | Q17: 8 | S17: 9 | U17: 10 | W17: 11 | Y17: 12 | AA17: T. REV | AB17: TOTAL
A18: B | B18: OBRA GRUESA | C18: AT | D18: RV | E18: AT | F18: RV | G18: AT | H18: RV | I18: AT | J18: RV | K18: AT | L18: RV | M18: AT | N18: RV | O18: AT | P18: RV | Q18: AT | R18: RV | S18: AT | T18: RV | U18: AT | V18: RV | W18: AT | X18: RV | Y18: AT | Z18: RV
A19: B.1 | B19: FUNDACIONES
A20: B.1.1 | B20: Replanteo, trazado y niveles | C20: R5 | E20: R5 | G20: R5 | I20: R5 | K20: R4 | M20: R4 | O20: R4 | Q20: R5 | S20: R5 | U20: R5 | W20: R5 | Y20: R5 | AA20: =COUNTIF(C20:Z20,">=R") -> 12 | AB20: =AA20 -> 12
A21: B.1.2 | B21: Excavación | C21: R6 | E21: R6 | G21: R7 | I21: R7 | K21: R4 | M21: R4 | O21: R4 | Q21: R9 | S21: R6 | U21: R6 | W21: R6 | Y21: R6 | AA21: =COUNTIF(C21:Z21,">=R") -> 12 | AB21: =AA21 -> 12
A22: B.1.3 | B22: Emplantillado (G5) | C22: R26 | E22: R7 | G22: R7 | I22: R7 | K22: R5 | M22: R5 | O22: R5 | Q22: R9 | S22: R7 | U22: R7 | W22: R7 | Y22: R7 | AA22: =COUNTIF(C22:Z22,">=R") -> 12 | AB22: =AA22 -> 12
A23: B.1.4 | B23: Hormigón cimientos (G10) | C23: R7 | E23: R7 | G23: R7 | I23: R7 | K23: R5 | M23: R5 | O23: R5 | Q23: R9 | S23: R7 | U23: R7 | W23: R7 | Y23: R7 | AA23: =COUNTIF(C23:Z23,">=R") -> 12 | AB23: =AA23 -> 12
A24: B.1.5 | B24: Hormigón sobrecimientos (G17) | C24: R9 | E24: R9 | G24: R9 | I24: R9 | K24: R5 | M24: R5 | O24: R5 | Q24: R15 | S24: R9 | U24: R9 | W24: R9 | Y24: R9 | AA24: =COUNTIF(C24:Z24,">=R") -> 12 | AB24: =AA24 -> 12
